<sdf version='1.7'>
  <world name='default'>
    <model name='ground_plane'>
      <static>1</static>
      <link name='link'>
        <collision name='collision'>
          <geometry>
            <plane>
              <normal>0 0 1</normal>
              <size>100 100</size>
            </plane>
          </geometry>
          <surface>
            <contact>
              <collide_bitmask>65535</collide_bitmask>
              <ode/>
            </contact>
            <friction>
              <ode>
                <mu>100</mu>
                <mu2>50</mu2>
              </ode>
              <torsional>
                <ode/>
              </torsional>
            </friction>
            <bounce/>
          </surface>
          <max_contacts>10</max_contacts>
        </collision>
        <visual name='visual'>
          <cast_shadows>0</cast_shadows>
          <geometry>
            <plane>
              <normal>0 0 1</normal>
              <size>100 100</size>
            </plane>
          </geometry>
          <material>
            <script>
              <uri>file://media/materials/scripts/gazebo.material</uri>
              <name>Gazebo/Grey</name>
            </script>
          </material>
        </visual>
        <self_collide>0</self_collide>
        <enable_wind>0</enable_wind>
        <kinematic>0</kinematic>
      </link>
    </model>
    <light name='sun' type='directional'>
      <cast_shadows>1</cast_shadows>
      <pose>0 0 10 0 -0 0</pose>
      <diffuse>0.8 0.8 0.8 1</diffuse>
      <specular>0.2 0.2 0.2 1</specular>
      <attenuation>
        <range>1000</range>
        <constant>0.9</constant>
        <linear>0.01</linear>
        <quadratic>0.001</quadratic>
      </attenuation>
      <direction>-0.5 0.1 -0.9</direction>
      <spot>
        <inner_angle>0</inner_angle>
        <outer_angle>0</outer_angle>
        <falloff>0</falloff>
      </spot>
    </light>
    <gui fullscreen='0'>
      <camera name='user_camera'>
        <pose>-2.68747 -3.35426 27.3294 0 1.4138 1.716</pose>
        <view_controller>orbit</view_controller>
        <projection_type>perspective</projection_type>
      </camera>
    </gui>
    <model name='diablo'>
      <pose>0 0 0.3 0 -0 0</pose>
      <link name='Body'>
        <pose>0 0 0 0 -0 0</pose>
        <inertial>
          <mass>6.72372</mass>
          <inertia>
            <ixx>0.048353</ixx>
            <ixy>-1.87046e-06</ixy>
            <ixz>-0.00263124</ixz>
            <iyy>0.0715625</iyy>
            <iyz>7.09833e-06</iyz>
            <izz>0.0723919</izz>
          </inertia>
          <pose>0.01243 0.00015 -0.00675 0 -0 0</pose>
        </inertial>
        <self_collide>0</self_collide>
        <kinematic>0</kinematic>
        <gravity>1</gravity>
        <visual name='visual'>
          <pose>0 0 0 0 -0 0</pose>
          <material>
            <script>
              <name>Gazebo/DarkGrey</name>
              <uri>file://media/materials/scripts/gazebo.material</uri>
            </script>
          </material>
          <geometry>
            <mesh>
              <uri>model://DIABLO/STL/Body.stl</uri>
            </mesh>
          </geometry>
        </visual>
        <collision name='collision'>
          <laser_retro>0</laser_retro>
          <max_contacts>10</max_contacts>
          <pose>0 0 0 0 -0 0</pose>
          <geometry>
            <mesh>
              <uri>model://DIABLO/STL/Body.stl</uri>
            </mesh>
          </geometry>
          <surface>
            <friction>
              <ode>
                <mu>0</mu>
                <mu2>0</mu2>
                <fdir1>0 0 0</fdir1>
                <slip1>0</slip1>
                <slip2>0</slip2>
              </ode>
              <torsional>
                <coefficient>1</coefficient>
                <patch_radius>0</patch_radius>
                <surface_radius>0</surface_radius>
                <use_patch_radius>1</use_patch_radius>
                <ode>
                  <slip>0</slip>
                </ode>
              </torsional>
            </friction>
            <bounce>
              <restitution_coefficient>0</restitution_coefficient>
              <threshold>1e+06</threshold>
            </bounce>
            <contact>
              <collide_without_contact>0</collide_without_contact>
              <collide_without_contact_bitmask>1</collide_without_contact_bitmask>
              <collide_bitmask>1</collide_bitmask>
              <ode>
                <soft_cfm>0</soft_cfm>
                <soft_erp>0.2</soft_erp>
                <kp>1e+13</kp>
                <kd>1</kd>
                <max_vel>0.01</max_vel>
                <min_depth>0</min_depth>
              </ode>
              <bullet>
                <split_impulse>1</split_impulse>
                <split_impulse_penetration_threshold>-0.01</split_impulse_penetration_threshold>
                <soft_cfm>0</soft_cfm>
                <soft_erp>0.2</soft_erp>
                <kp>1e+13</kp>
                <kd>1</kd>
              </bullet>
            </contact>
          </surface>
        </collision>
        <enable_wind>0</enable_wind>
      </link>
      <link name='Leg0_R'>
        <pose>0 -0.1238 0 0 0.785398 0</pose>
        <inertial>
          <mass>2.46054</mass>
          <inertia>
            <ixx>0.00853722</ixx>
            <ixy>-5.57176e-06</ixy>
            <ixz>-7.947e-08</ixz>
            <iyy>0.00817364</iyy>
            <iyz>0.000205997</iyz>
            <izz>0.00794292</izz>
          </inertia>
          <pose>-0.00036 0.01353 -0.00417 0 -0 0</pose>
        </inertial>
        <self_collide>0</self_collide>
        <kinematic>0</kinematic>
        <gravity>1</gravity>
        <visual name='visual'>
          <pose>0 0 0 0 -0 0</pose>
          <geometry>
            <mesh>
              <uri>model://DIABLO/STL/Leg_0.stl</uri>
            </mesh>
          </geometry>
        </visual>
        <enable_wind>0</enable_wind>
      </link>
      <link name='Leg0_L'>
        <pose>0 0.12375 0 0 -0.785398 3.14159</pose>
        <inertial>
          <mass>2.46054</mass>
          <inertia>
            <ixx>0.00853722</ixx>
            <ixy>-5.57176e-06</ixy>
            <ixz>-7.947e-08</ixz>
            <iyy>0.00817364</iyy>
            <iyz>0.000205997</iyz>
            <izz>0.00794292</izz>
          </inertia>
          <pose>-0.00036 0.01353 -0.00417 0 -0 0</pose>
        </inertial>
        <self_collide>0</self_collide>
        <kinematic>0</kinematic>
        <gravity>1</gravity>
        <visual name='visual'>
          <pose>0 0 0 0 -0 0</pose>
          <geometry>
            <mesh>
              <uri>model://DIABLO/STL/Leg_0.stl</uri>
            </mesh>
          </geometry>
        </visual>
        <enable_wind>0</enable_wind>
      </link>
      <link name='Leg1_R'>
        <pose>0 -0.17625 0 0 0.785398 3.14159</pose>
        <inertial>
          <mass>1.24694</mass>
          <inertia>
            <ixx>0.00293799</ixx>
            <ixy>-3.88314e-05</ixy>
            <ixz>9.80999e-05</ixz>
            <iyy>0.00343778</iyy>
            <iyz>-4.62549e-05</iyz>
            <izz>0.00226058</izz>
          </inertia>
          <pose>-0.00012 -0.02373 -0.00534 0 -0 0</pose>
        </inertial>
        <self_collide>0</self_collide>
        <kinematic>0</kinematic>
        <gravity>1</gravity>
        <visual name='visual'>
          <material>
            <script>
              <name>Gazebo/DarkGrey</name>
              <uri>file://media/materials/scripts/gazebo.material</uri>
            </script>
          </material>
          <pose>0 0 0 0 -0 0</pose>
          <geometry>
            <mesh>
              <uri>model://DIABLO/STL/Leg_1_R.stl</uri>
            </mesh>
          </geometry>
        </visual>
        <enable_wind>0</enable_wind>
      </link>
      <link name='Leg1_L'>
        <pose>0 0.17625 0 0 -0.785398 0</pose>
        <inertial>
          <mass>1.24694</mass>
          <inertia>
            <ixx>0.00282972</ixx>
            <ixy>-1.80804e-05</ixy>
            <ixz>-9.87201e-05</ixz>
            <iyy>0.00344247</iyy>
            <iyz>-6.0529e-05</iyz>
            <izz>0.00214713</izz>
          </inertia>
          <pose>0.00196 -0.02373 -0.00534 0 -0 0</pose>
        </inertial>
        <self_collide>0</self_collide>
        <kinematic>0</kinematic>
        <gravity>1</gravity>
        <visual name='visual'>
          <material>
            <script>
              <name>Gazebo/DarkGrey</name>
              <uri>file://media/materials/scripts/gazebo.material</uri>
            </script>
          </material>
          <pose>0 0 0 0 -0 0</pose>
          <geometry>
            <mesh>
              <uri>model://DIABLO/STL/Leg_1_L.stl</uri>
            </mesh>
          </geometry>
        </visual>
        <enable_wind>0</enable_wind>
      </link>
      <link name='Leg2_R'>
        <pose>-0.06364 -0.17625 -0.06364 0 -0.785398 0</pose>
        <inertial>
          <mass>0.10247</mass>
          <inertia>
            <ixx>0.000812662</ixx>
            <ixy>1.33486e-05</ixy>
            <ixz>0.000129647</ixz>
            <iyy>0.000855323</iyy>
            <iyz>6.24627e-05</iyz>
            <izz>6.02294e-05</izz>
          </inertia>
          <pose>-0.01628 -0.008 -0.07331 0 -0 0</pose>
        </inertial>
        <self_collide>0</self_collide>
        <kinematic>0</kinematic>
        <gravity>1</gravity>
        <visual name='visual'>
          <material>
            <script>
              <name>Gazebo/DarkGrey</name>
              <uri>file://media/materials/scripts/gazebo.material</uri>
            </script>
          </material>
          <pose>0 0 0 0 -0 0</pose>
          <geometry>
            <mesh>
              <uri>model://DIABLO/STL/Leg_2.stl</uri>
            </mesh>
          </geometry>
        </visual>
        <enable_wind>0</enable_wind>
      </link>
      <link name='Leg2_L'>
        <pose>-0.06364 0.19225 -0.06364 0 -0.785398 0</pose>
        <inertial>
          <mass>0.10247</mass>
          <inertia>
            <ixx>0.000812662</ixx>
            <ixy>1.33486e-05</ixy>
            <ixz>0.000129647</ixz>
            <iyy>0.000855323</iyy>
            <iyz>6.24627e-05</iyz>
            <izz>6.02294e-05</izz>
          </inertia>
          <pose>-0.01628 -0.008 -0.07331 0 -0 0</pose>
        </inertial>
        <self_collide>0</self_collide>
        <kinematic>0</kinematic>
        <gravity>1</gravity>
        <visual name='visual'>
          <material>
            <script>
              <name>Gazebo/DarkGrey</name>
              <uri>file://media/materials/scripts/gazebo.material</uri>
            </script>
          </material>
          <pose>0 0 0 0 -0 0</pose>
          <geometry>
            <mesh>
              <uri>model://DIABLO/STL/Leg_2.stl</uri>
            </mesh>
          </geometry>
        </visual>
        <enable_wind>0</enable_wind>
      </link>
      <link name='Leg3_R'>
        <pose>0 -0.2155 -0.19799 0 0.785398 0</pose>
        <inertial>
          <mass>1.29685</mass>
          <inertia>
            <ixx>0.0030283</ixx>
            <ixy>-3.26753e-05</ixy>
            <ixz>-0.000187261</ixz>
            <iyy>0.00363171</iyy>
            <iyz>-0.000161802</iyz>
            <izz>0.00218078</izz>
          </inertia>
          <pose>-0.00127 -0.02001 0.00598 0 -0 0</pose>
        </inertial>
        <self_collide>0</self_collide>
        <kinematic>0</kinematic>
        <gravity>1</gravity>
        <visual name='visual'>
          <material>
            <script>
              <name>Gazebo/Grey</name>
              <uri>file://media/materials/scripts/gazebo.material</uri>
            </script>
          </material>
          <pose>0 0 0 0 -0 0</pose>
          <geometry>
            <mesh>
              <uri>model://DIABLO/STL/Leg_3.stl</uri>
            </mesh>
          </geometry>
        </visual>
        <enable_wind>0</enable_wind>
      </link>
      <link name='Leg3_L'>
        <pose>0 0.2155 -0.19799 0 -0.785398 3.14159</pose>
        <inertial>
          <mass>1.29685</mass>
          <inertia>
            <ixx>0.0030283</ixx>
            <ixy>-3.26753e-05</ixy>
            <ixz>-0.000187261</ixz>
            <iyy>0.00363171</iyy>
            <iyz>-0.000161802</iyz>
            <izz>0.00218078</izz>
          </inertia>
          <pose>-0.00127 -0.02001 0.00598 0 -0 0</pose>
        </inertial>
        <self_collide>0</self_collide>
        <kinematic>0</kinematic>
        <gravity>1</gravity>
        <visual name='visual'>
          <material>
            <script>
              <name>Gazebo/Grey</name>
              <uri>file://media/materials/scripts/gazebo.material</uri>
            </script>
          </material>
          <pose>0 0 0 0 -0 0</pose>
          <geometry>
            <mesh>
              <uri>model://DIABLO/STL/Leg_3.stl</uri>
            </mesh>
          </geometry>
        </visual>
        <enable_wind>0</enable_wind>
      </link>
      <link name='Wheel_R'>
        <pose>0 -0.24625 -0.19799 0 -0 0</pose>
        <inertial>
          <mass>1.36187</mass>
          <inertia>
            <ixx>0.00349977</ixx>
            <ixy>0</ixy>
            <ixz>0</ixz>
            <iyy>0.00660656</iyy>
            <iyz>0</iyz>
            <izz>0.00349977</izz>
          </inertia>
          <pose>0 0 0 0 -0 0</pose>
        </inertial>
        <self_collide>0</self_collide>
        <kinematic>0</kinematic>
        <gravity>1</gravity>
        <visual name='visual'>
          <material>
            <script>
              <name>Gazebo/Red</name>
              <uri>file://media/materials/scripts/gazebo.material</uri>
            </script>
          </material>
          <pose>0 0 0 0 -0 0</pose>
          <geometry>
            <mesh>
              <uri>model://DIABLO/STL/Wheel.stl</uri>
            </mesh>
          </geometry>
        </visual>
        <visual name='visual_guide'>
          <material>
            <script>
              <name>Gazebo/Black</name>
              <uri>file://media/materials/scripts/gazebo.material</uri>
            </script>
          </material>
          <pose>0.05 -0.03 0 0 -0 0</pose>
          <geometry>
            <sphere>
              <radius>0.008</radius>
            </sphere>
          </geometry>
        </visual>
        <collision name='collision'>
          <laser_retro>0</laser_retro>
          <max_contacts>10</max_contacts>
          <pose>0 0 0 0 -0 0</pose>
          <geometry>
            <mesh>
              <uri>model://DIABLO/STL/Wheel.stl</uri>
            </mesh>
          </geometry>
          <surface>
            <friction>
              <ode>
                <mu>0.7</mu>
                <mu2>0.7</mu2>
                <fdir1>0 0 0</fdir1>
                <slip1>0</slip1>
                <slip2>0</slip2>
              </ode>
              <torsional>
                <coefficient>1</coefficient>
                <patch_radius>0</patch_radius>
                <surface_radius>0</surface_radius>
                <use_patch_radius>1</use_patch_radius>
                <ode>
                  <slip>0</slip>
                </ode>
              </torsional>
            </friction>
            <bounce>
              <restitution_coefficient>0</restitution_coefficient>
              <threshold>1e+06</threshold>
            </bounce>
            <contact>
              <collide_without_contact>0</collide_without_contact>
              <collide_without_contact_bitmask>1</collide_without_contact_bitmask>
              <collide_bitmask>65535</collide_bitmask>
              <ode>
                <soft_cfm>0</soft_cfm>
                <soft_erp>0.2</soft_erp>
                <kp>1e+13</kp>
                <kd>1</kd>
                <max_vel>0.01</max_vel>
                <min_depth>0.001</min_depth>
              </ode>
            </contact>
          </surface>
        </collision>
        <enable_wind>0</enable_wind>
      </link>
      <link name='Wheel_L'>
        <pose>0 0.24625 -0.19799 0 -0 3.14159</pose>
        <inertial>
          <mass>1.36187</mass>
          <inertia>
            <ixx>0.00349977</ixx>
            <ixy>0</ixy>
            <ixz>0</ixz>
            <iyy>0.00660656</iyy>
            <iyz>0</iyz>
            <izz>0.00349977</izz>
          </inertia>
          <pose>0 0 0 0 -0 0</pose>
        </inertial>
        <self_collide>0</self_collide>
        <kinematic>0</kinematic>
        <gravity>1</gravity>
        <visual name='visual'>
          <material>
            <script>
              <name>Gazebo/Blue</name>
              <uri>file://media/materials/scripts/gazebo.material</uri>
            </script>
          </material>
          <pose>0 0 0 0 -0 0</pose>
          <geometry>
            <mesh>
              <uri>model://DIABLO/STL/Wheel.stl</uri>
            </mesh>
          </geometry>
        </visual>
        <visual name='visual_guide'>
          <material>
            <script>
              <name>Gazebo/Black</name>
              <uri>file://media/materials/scripts/gazebo.material</uri>
            </script>
          </material>
          <pose>0.05 -0.03 0 0 -0 0</pose>
          <geometry>
            <sphere>
              <radius>0.008</radius>
            </sphere>
          </geometry>
        </visual>
        <collision name='collision'>
          <laser_retro>0</laser_retro>
          <max_contacts>10</max_contacts>
          <pose>0 0 0 0 -0 0</pose>
          <geometry>
            <mesh>
              <uri>model://DIABLO/STL/Wheel.stl</uri>
            </mesh>
          </geometry>
          <surface>
            <friction>
              <ode>
                <mu>0.7</mu>
                <mu2>0.7</mu2>
                <fdir1>0 0 0</fdir1>
                <slip1>0</slip1>
                <slip2>0</slip2>
              </ode>
              <torsional>
                <coefficient>1</coefficient>
                <patch_radius>0</patch_radius>
                <surface_radius>0</surface_radius>
                <use_patch_radius>1</use_patch_radius>
                <ode>
                  <slip>0</slip>
                </ode>
              </torsional>
            </friction>
            <bounce>
              <restitution_coefficient>0</restitution_coefficient>
              <threshold>1e+06</threshold>
            </bounce>
            <contact>
              <collide_without_contact>0</collide_without_contact>
              <collide_without_contact_bitmask>1</collide_without_contact_bitmask>
              <collide_bitmask>65535</collide_bitmask>
              <ode>
                <soft_cfm>0</soft_cfm>
                <soft_erp>0.2</soft_erp>
                <kp>1e+13</kp>
                <kd>1</kd>
                <max_vel>0.01</max_vel>
                <min_depth>0.001</min_depth>
              </ode>
            </contact>
          </surface>
        </collision>
        <enable_wind>0</enable_wind>
      </link>
      <joint name='Motor0_L' type='revolute'>
        <parent>Body</parent>
        <child>Leg0_L</child>
        <pose>0 0 0 0 -0 0</pose>
        <axis>
          <xyz expressed_in='__model__'>0 1 0</xyz>
          <limit>
            <lower>-1.53</lower>
            <upper>1.56</upper>
            <effort>200</effort>
            <velocity>100</velocity>
          </limit>
          <dynamics>
            <damping>0</damping>
            <friction>0</friction>
            <spring_reference>0</spring_reference>
            <spring_stiffness>0</spring_stiffness>
          </dynamics>
        </axis>
        <physics>
          <ode>
            <limit>
              <cfm>0</cfm>
              <erp>0.2</erp>
            </limit>
            <suspension>
              <cfm>0</cfm>
              <erp>0.2</erp>
            </suspension>
          </ode>
        </physics>
      </joint>
      <joint name='Motor0_R' type='revolute'>
        <parent>Body</parent>
        <child>Leg0_R</child>
        <pose>0 0 0 0 -0 0</pose>
        <axis>
          <xyz expressed_in='__model__'>0 1 0</xyz>
          <limit>
            <lower>-1.53</lower>
            <upper>1.56</upper>
            <effort>200</effort>
            <velocity>100</velocity>
          </limit>
          <dynamics>
            <damping>0</damping>
            <friction>0</friction>
            <spring_reference>0</spring_reference>
            <spring_stiffness>0</spring_stiffness>
          </dynamics>
        </axis>
        <physics>
          <ode>
            <limit>
              <cfm>0</cfm>
              <erp>0.2</erp>
            </limit>
            <suspension>
              <cfm>0</cfm>
              <erp>0.2</erp>
            </suspension>
          </ode>
        </physics>
      </joint>
      <joint name='Motor1_L' type='revolute'>
        <parent>Leg0_L</parent>
        <child>Leg1_L</child>
        <pose>0 0 0 0 -0 0</pose>
        <axis>
          <xyz expressed_in='__model__'>0 1 0</xyz>
          <limit>
            <lower>-1</lower>
            <upper>1</upper>
            <effort>1000</effort>
            <velocity>500</velocity>
          </limit>
          <dynamics>
            <damping>0</damping>
            <friction>0</friction>
            <spring_reference>0</spring_reference>
            <spring_stiffness>0</spring_stiffness>
          </dynamics>
        </axis>
        <physics>
          <ode>
            <limit>
              <cfm>0</cfm>
              <erp>0.2</erp>
            </limit>
            <suspension>
              <cfm>0</cfm>
              <erp>0.2</erp>
            </suspension>
          </ode>
        </physics>
      </joint>
      <joint name='Motor1_R' type='revolute'>
        <parent>Leg0_R</parent>
        <child>Leg1_R</child>
        <pose>0 0 0 0 -0 0</pose>
        <axis>
          <xyz expressed_in='__model__'>0 1 0</xyz>
          <limit>
            <lower>-1</lower>
            <upper>1</upper>
            <effort>1000</effort>
            <velocity>500</velocity>
          </limit>
          <dynamics>
            <damping>0</damping>
            <friction>0</friction>
            <spring_reference>0</spring_reference>
            <spring_stiffness>0</spring_stiffness>
          </dynamics>
        </axis>
        <physics>
          <ode>
            <limit>
              <cfm>0</cfm>
              <erp>0.2</erp>
            </limit>
            <suspension>
              <cfm>0</cfm>
              <erp>0.2</erp>
            </suspension>
          </ode>
        </physics>
      </joint>
      <joint name='J1_L' type='revolute'>
        <parent>Leg0_L</parent>
        <child>Leg2_L</child>
        <pose>0 0 0 0 -0 0</pose>
        <axis>
          <xyz expressed_in='__model__'>0 1 0</xyz>
          <limit>
            <lower>-0.5</lower>
            <upper>0.5</upper>
          </limit>
          <dynamics>
            <damping>0.2</damping>
            <friction>0.1</friction>
            <spring_reference>0</spring_reference>
            <spring_stiffness>0</spring_stiffness>
          </dynamics>
        </axis>
        <physics>
          <ode>
            <suspension>
              <cfm>0</cfm>
              <erp>0.2</erp>
            </suspension>
            <limit>
              <cfm>0</cfm>
              <erp>0.2</erp>
            </limit>
          </ode>
        </physics>
      </joint>
      <joint name='J1_R' type='revolute'>
        <parent>Leg0_R</parent>
        <child>Leg2_R</child>
        <pose>0 0 0 0 -0 0</pose>
        <axis>
          <xyz expressed_in='__model__'>0 1 0</xyz>
          <limit>
            <lower>-0.5</lower>
            <upper>0.5</upper>
          </limit>
          <dynamics>
            <damping>0.2</damping>
            <friction>0.1</friction>
            <spring_reference>0</spring_reference>
            <spring_stiffness>0</spring_stiffness>
          </dynamics>
        </axis>
        <physics>
          <ode>
            <suspension>
              <cfm>0</cfm>
              <erp>0.2</erp>
            </suspension>
            <limit>
              <cfm>0</cfm>
              <erp>0.2</erp>
            </limit>
          </ode>
        </physics>
      </joint>
      <joint name='J2_L' type='revolute'>
        <parent>Leg1_L</parent>
        <child>Leg3_L</child>
        <pose>0 0 0.14 0 -0 0</pose>
        <axis>
          <xyz expressed_in='__model__'>0 1 0</xyz>
          <limit>
            <lower>-0.5</lower>
            <upper>0.5</upper>
          </limit>
          <dynamics>
            <damping>0.2</damping>
            <friction>0.1</friction>
            <spring_reference>0</spring_reference>
            <spring_stiffness>0</spring_stiffness>
          </dynamics>
        </axis>
        <physics>
          <ode>
            <suspension>
              <cfm>0</cfm>
              <erp>0.2</erp>
            </suspension>
            <limit>
              <cfm>0</cfm>
              <erp>0.2</erp>
            </limit>
          </ode>
        </physics>
      </joint>
      <joint name='J2_R' type='revolute'>
        <parent>Leg1_R</parent>
        <child>Leg3_R</child>
        <pose>0 0 0.14 0 -0 0</pose>
        <axis>
          <xyz expressed_in='__model__'>0 1 0</xyz>
          <limit>
            <lower>-0.5</lower>
            <upper>0.5</upper>
          </limit>
          <dynamics>
            <damping>0.2</damping>
            <friction>0.1</friction>
            <spring_reference>0</spring_reference>
            <spring_stiffness>0</spring_stiffness>
          </dynamics>
        </axis>
        <physics>
          <ode>
            <suspension>
              <cfm>0</cfm>
              <erp>0.2</erp>
            </suspension>
            <limit>
              <cfm>0</cfm>
              <erp>0.2</erp>
            </limit>
          </ode>
        </physics>
      </joint>
      <joint name='J3_L' type='revolute'>
        <parent>Leg2_L</parent>
        <child>Leg3_L</child>
        <pose>0 0 0.05 0 -0 0</pose>
        <axis>
          <xyz expressed_in='__model__'>0 1 0</xyz>
          <limit>
            <lower>-0.5</lower>
            <upper>0.5</upper>
          </limit>
          <dynamics>
            <damping>0.2</damping>
            <friction>0.1</friction>
            <spring_reference>0</spring_reference>
            <spring_stiffness>0</spring_stiffness>
          </dynamics>
        </axis>
        <physics>
          <ode>
            <limit>
              <cfm>0</cfm>
              <erp>0.2</erp>
            </limit>
            <suspension>
              <cfm>0</cfm>
              <erp>0.2</erp>
            </suspension>
          </ode>
        </physics>
      </joint>
      <joint name='J3_R' type='revolute'>
        <parent>Leg2_R</parent>
        <child>Leg3_R</child>
        <pose>0 0 0.05 0 -0 0</pose>
        <axis>
          <xyz expressed_in='__model__'>0 1 0</xyz>
          <limit>
            <lower>-0.5</lower>
            <upper>0.5</upper>
          </limit>
          <dynamics>
            <damping>0.2</damping>
            <friction>0.1</friction>
            <spring_reference>0</spring_reference>
            <spring_stiffness>0</spring_stiffness>
          </dynamics>
        </axis>
        <physics>
          <ode>
            <limit>
              <cfm>0</cfm>
              <erp>0.2</erp>
            </limit>
            <suspension>
              <cfm>0</cfm>
              <erp>0.2</erp>
            </suspension>
          </ode>
        </physics>
      </joint>
      <joint name='Motor2_L' type='revolute'>
        <parent>Leg3_L</parent>
        <child>Wheel_L</child>
        <pose>0 0 0 0 -0 0</pose>
        <axis>
          <xyz expressed_in='__model__'>0 1 0</xyz>
          <dynamics>
            <damping>0</damping>
            <friction>0</friction>
            <spring_reference>0</spring_reference>
            <spring_stiffness>0</spring_stiffness>
          </dynamics>
          <limit>
            <effort>1000</effort>
            <velocity>1000</velocity>
            <lower>-1e+16</lower>
            <upper>1e+16</upper>
          </limit>
        </axis>
        <physics>
          <ode>
            <limit>
              <cfm>0</cfm>
              <erp>0.2</erp>
            </limit>
            <suspension>
              <cfm>0</cfm>
              <erp>0.2</erp>
            </suspension>
          </ode>
        </physics>
      </joint>
      <joint name='Motor2_R' type='revolute'>
        <parent>Leg3_R</parent>
        <child>Wheel_R</child>
        <pose>0 0 0 0 -0 0</pose>
        <axis>
          <xyz expressed_in='__model__'>0 1 0</xyz>
          <limit>
            <effort>1000</effort>
            <velocity>1000</velocity>
            <lower>-1e+16</lower>
            <upper>1e+16</upper>
          </limit>
          <dynamics>
            <spring_reference>0</spring_reference>
            <spring_stiffness>0</spring_stiffness>
          </dynamics>
        </axis>
        <physics>
          <ode>
            <limit>
              <cfm>0</cfm>
              <erp>0.2</erp>
            </limit>
            <suspension>
              <cfm>0</cfm>
              <erp>0.2</erp>
            </suspension>
          </ode>
        </physics>
      </joint>
      <plugin name='M1R' filename='libgeneric_motor_plugin.so'>
        <namespace>diablo</namespace>
        <joint_name>Motor0_R</joint_name>
        <Kp>180.0</Kp>
        <Kd>10.0</Kd>
        <Ki>3.0</Ki>
      </plugin>
      <plugin name='M2R' filename='libgeneric_motor_plugin.so'>
        <namespace>diablo</namespace>
        <joint_name>Motor1_R</joint_name>
        <Kp>150.0</Kp>
        <Kd>10.0</Kd>
        <Ki>3.0</Ki>
      </plugin>
      <plugin name='M3R' filename='libgeneric_motor_plugin.so'>
        <namespace>diablo</namespace>
        <joint_name>Motor2_R</joint_name>
        <Kp>20.0</Kp>
        <Kd>2.0</Kd>
        <Ki>0.5</Ki>
      </plugin>
      <plugin name='M1L' filename='libgeneric_motor_plugin.so'>
        <namespace>diablo</namespace>
        <joint_name>Motor0_L</joint_name>
        <Kp>180.0</Kp>
        <Kd>10.0</Kd>
        <Ki>3.0</Ki>
      </plugin>
      <plugin name='M2L' filename='libgeneric_motor_plugin.so'>
        <namespace>diablo</namespace>
        <joint_name>Motor1_L</joint_name>
        <Kp>150.0</Kp>
        <Kd>10.0</Kd>
        <Ki>3.0</Ki>
      </plugin>
      <plugin name='M3L' filename='libgeneric_motor_plugin.so'>
        <namespace>diablo</namespace>
        <joint_name>Motor2_L</joint_name>
        <Kp>20.0</Kp>
        <Kd>2.0</Kd>
        <Ki>0.5</Ki>
      </plugin>
      <joint name='imu_joint' type='fixed'>
        <parent>Body</parent>
        <child>imu_link</child>
      </joint>
      <link name='imu_link'>
        <inertial>
          <pose>0 0 0 0 -0 0</pose>
          <mass>0.1</mass>
          <inertia>
            <ixx>0.001</ixx>
            <ixy>0</ixy>
            <ixz>0</ixz>
            <iyy>0.001</iyy>
            <iyz>0</iyz>
            <izz>0.002</izz>
          </inertia>
        </inertial>
        <visual name='imu_visual'>
          <pose>0 0 0 0 -0 0</pose>
          <geometry>
            <sphere>
              <radius>0.01</radius>
            </sphere>
          </geometry>
        </visual>
        <collision name='imu_collision'>
          <pose>0 0 0 0 -0 0</pose>
          <geometry>
            <sphere>
              <radius>0.01</radius>
            </sphere>
          </geometry>
          <max_contacts>10</max_contacts>
          <surface>
            <contact>
              <ode/>
            </contact>
            <bounce/>
            <friction>
              <torsional>
                <ode/>
              </torsional>
              <ode/>
            </friction>
          </surface>
        </collision>
        <sensor name='imu_sensor' type='imu'>
          <always_on>1</always_on>
          <update_rate>1000</update_rate>
          <pose>0 0 0 0 -0 0</pose>
          <topic>__default_topic__</topic>
          <plugin name='imu_plugin' filename='libgazebo_ros_imu_sensor.so'>
            <topicName>imu</topicName>
            <bodyName>imu_link</bodyName>
            <updateRateHZ>1000.0</updateRateHZ>
            <gaussianNoise>0.0001</gaussianNoise>
            <xyzOffset>0 0 0</xyzOffset>
            <rpyOffset>0 0 0</rpyOffset>
            <frameName>imu_link</frameName>
            <initialOrientationAsReference>0</initialOrientationAsReference>
          </plugin>
          <imu/>
        </sensor>
        <self_collide>0</self_collide>
        <enable_wind>0</enable_wind>
        <kinematic>0</kinematic>
      </link>
      <plugin name='low_lvl_controller' filename='liblow_ctrl_plugin.so'>
        <namespace>diablo</namespace>
      </plugin>
      <joint name='base_to_lidar' type='fixed'>
        <parent>Body</parent>
        <child>base_link</child>
        <pose>0 0 0 0 -0 0</pose>
        <axis>
          <dynamics>
            <damping>0</damping>
            <friction>0</friction>
            <spring_reference>0</spring_reference>
            <spring_stiffness>0</spring_stiffness>
          </dynamics>
          <xyz expressed_in='__model__'>0 0 1</xyz>
          <limit>
            <lower>-1e+16</lower>
            <upper>1e+16</upper>
          </limit>
        </axis>
        <physics>
          <ode>
            <limit>
              <cfm>0</cfm>
              <erp>0.2</erp>
            </limit>
            <suspension>
              <cfm>0</cfm>
              <erp>0.2</erp>
            </suspension>
          </ode>
        </physics>
      </joint>
      <link name='base_link'>
        <inertial>
          <pose>0 0 0.13 0 -0 0</pose>
          <mass>0.84</mass>
          <inertia>
            <ixx>0.000908193</ixx>
            <ixy>0</ixy>
            <ixz>0</ixz>
            <iyy>0.000908193</iyy>
            <iyz>0</iyz>
            <izz>0.00110506</izz>
          </inertia>
        </inertial>
        <sensor name='velodyne-VLP16' type='ray'>
          <visualize>0</visualize>
          <update_rate>10</update_rate>
          <ray>
            <scan>
              <horizontal>
                <samples>440</samples>
                <resolution>1</resolution>
                <min_angle>-3.14159</min_angle>
                <max_angle>3.14159</max_angle>
              </horizontal>
              <vertical>
                <samples>16</samples>
                <resolution>1</resolution>
                <min_angle>-0.261799</min_angle>
                <max_angle>0.261799</max_angle>
              </vertical>
            </scan>
            <range>
              <min>0.3</min>
              <max>131</max>
              <resolution>0.001</resolution>
            </range>
            <noise>
              <type>gaussian</type>
              <mean>0</mean>
              <stddev>0</stddev>
            </noise>
          </ray>
          <plugin name='gazebo_ros_laser_controller' filename='libgazebo_ros_velodyne_laser.so'>
            <topicName>/velodyne_points</topicName>
            <frameName>velodyne</frameName>
            <organize_cloud>0</organize_cloud>
            <min_range>0.9</min_range>
            <max_range>130.0</max_range>
            <gaussianNoise>0.008</gaussianNoise>
            <robotNamespace>/</robotNamespace>
          </plugin>
          <pose>0 0 0.13 0 -0 0</pose>
        </sensor>
        <self_collide>0</self_collide>
        <enable_wind>0</enable_wind>
        <kinematic>0</kinematic>
        <pose>0 0 0 0 -0 0</pose>
        <visual name='base_link_fixed_joint_lump__velodyne_base_link_visual'>
          <pose>0 0 0.13 0 -0 0</pose>
          <geometry>
            <mesh>
              <scale>1 1 1</scale>
              <uri>/home/jya9538/Projects/Diablo/src/velodyne_simulator/velodyne_description/meshes/VLP16_base_1.dae</uri>
            </mesh>
          </geometry>
          <material>
            <shader type='pixel'/>
          </material>
          <transparency>0</transparency>
          <cast_shadows>1</cast_shadows>
        </visual>
        <visual name='base_link_fixed_joint_lump__velodyne_base_link_visual_1'>
          <pose>0 0 0.13 0 -0 0</pose>
          <geometry>
            <mesh>
              <scale>1 1 1</scale>
              <uri>/home/jya9538/Projects/Diablo/src/velodyne_simulator/velodyne_description/meshes/VLP16_base_2.dae</uri>
            </mesh>
          </geometry>
          <material>
            <shader type='pixel'/>
          </material>
          <transparency>0</transparency>
          <cast_shadows>1</cast_shadows>
        </visual>
        <visual name='base_link_fixed_joint_lump__velodyne_visual_2'>
          <pose>0 0 0.13 0 -0 0</pose>
          <geometry>
            <mesh>
              <scale>1 1 1</scale>
              <uri>/home/jya9538/Projects/Diablo/src/velodyne_simulator/velodyne_description/meshes/VLP16_scan.dae</uri>
            </mesh>
          </geometry>
          <material>
            <shader type='pixel'/>
          </material>
          <transparency>0</transparency>
          <cast_shadows>1</cast_shadows>
        </visual>
        <collision name='base_link_fixed_joint_lump__velodyne_base_link_collision'>
          <laser_retro>0</laser_retro>
          <max_contacts>10</max_contacts>
          <pose>0 0 0.13 0 -0 0</pose>
          <geometry>
            <cylinder>
              <radius>0.0516</radius>
              <length>0.0717</length>
            </cylinder>
          </geometry>
          <surface>
            <friction>
              <ode>
                <mu>1</mu>
                <mu2>1</mu2>
                <fdir1>0 0 0</fdir1>
                <slip1>0</slip1>
                <slip2>0</slip2>
              </ode>
              <torsional>
                <coefficient>1</coefficient>
                <patch_radius>0</patch_radius>
                <surface_radius>0</surface_radius>
                <use_patch_radius>1</use_patch_radius>
                <ode>
                  <slip>0</slip>
                </ode>
              </torsional>
            </friction>
            <bounce>
              <restitution_coefficient>0</restitution_coefficient>
              <threshold>1e+06</threshold>
            </bounce>
            <contact>
              <collide_without_contact>0</collide_without_contact>
              <collide_without_contact_bitmask>1</collide_without_contact_bitmask>
              <collide_bitmask>1</collide_bitmask>
              <ode>
                <soft_cfm>0</soft_cfm>
                <soft_erp>0.2</soft_erp>
                <kp>1e+13</kp>
                <kd>1</kd>
                <max_vel>0.01</max_vel>
                <min_depth>0</min_depth>
              </ode>
              <bullet>
                <split_impulse>1</split_impulse>
                <split_impulse_penetration_threshold>-0.01</split_impulse_penetration_threshold>
                <soft_cfm>0</soft_cfm>
                <soft_erp>0.2</soft_erp>
                <kp>1e+13</kp>
                <kd>1</kd>
              </bullet>
            </contact>
          </surface>
        </collision>
        <collision name='base_link_fixed_joint_lump__velodyne_collision_1'>
          <laser_retro>0</laser_retro>
          <max_contacts>10</max_contacts>
          <pose>0 0 0.13 0 -0 0</pose>
          <geometry>
            <sphere>
              <radius>0</radius>
            </sphere>
          </geometry>
          <surface>
            <friction>
              <ode>
                <mu>1</mu>
                <mu2>1</mu2>
                <fdir1>0 0 0</fdir1>
                <slip1>0</slip1>
                <slip2>0</slip2>
              </ode>
              <torsional>
                <coefficient>1</coefficient>
                <patch_radius>0</patch_radius>
                <surface_radius>0</surface_radius>
                <use_patch_radius>1</use_patch_radius>
                <ode>
                  <slip>0</slip>
                </ode>
              </torsional>
            </friction>
            <bounce>
              <restitution_coefficient>0</restitution_coefficient>
              <threshold>1e+06</threshold>
            </bounce>
            <contact>
              <collide_without_contact>0</collide_without_contact>
              <collide_without_contact_bitmask>1</collide_without_contact_bitmask>
              <collide_bitmask>1</collide_bitmask>
              <ode>
                <soft_cfm>0</soft_cfm>
                <soft_erp>0.2</soft_erp>
                <kp>1e+13</kp>
                <kd>1</kd>
                <max_vel>0.01</max_vel>
                <min_depth>0</min_depth>
              </ode>
              <bullet>
                <split_impulse>1</split_impulse>
                <split_impulse_penetration_threshold>-0.01</split_impulse_penetration_threshold>
                <soft_cfm>0</soft_cfm>
                <soft_erp>0.2</soft_erp>
                <kp>1e+13</kp>
                <kd>1</kd>
              </bullet>
            </contact>
          </surface>
        </collision>
      </link>
      <static>0</static>
    </model>
    <spherical_coordinates>
      <surface_model>EARTH_WGS84</surface_model>
      <latitude_deg>47.3667</latitude_deg>
      <longitude_deg>8.55</longitude_deg>
      <elevation>500</elevation>
      <heading_deg>0</heading_deg>
    </spherical_coordinates>
    <physics type='ode'>
      <ode>
        <solver>
          <type>quick</type>
          <iters>500</iters>
          <sor>1.3</sor>
          <use_dynamic_moi_rescaling>0</use_dynamic_moi_rescaling>
        </solver>
        <constraints>
          <cfm>0</cfm>
          <erp>0.2</erp>
          <contact_max_correcting_vel>100</contact_max_correcting_vel>
          <contact_surface_layer>0.001</contact_surface_layer>
        </constraints>
      </ode>
      <max_step_size>0.001</max_step_size>
      <real_time_factor>1</real_time_factor>
      <real_time_update_rate>1000</real_time_update_rate>
    </physics>
    <gravity>0 0 -9.8</gravity>
    <magnetic_field>6e-06 2.3e-05 -4.2e-05</magnetic_field>
    <atmosphere type='adiabatic'/>
    <scene>
      <ambient>0.4 0.4 0.4 1</ambient>
      <background>0.7 0.7 0.7 1</background>
      <shadows>1</shadows>
    </scene>
    <wind/>
    <model name='environment'>
      <pose>0.248998 1.31866 0 0 -0 0</pose>
      <link name='Wall_1'>
        <collision name='Wall_1_Collision'>
          <geometry>
            <box>
              <size>12 0.15 2.5</size>
            </box>
          </geometry>
          <pose>0 0 1.25 0 -0 0</pose>
          <max_contacts>10</max_contacts>
          <surface>
            <contact>
              <ode/>
            </contact>
            <bounce/>
            <friction>
              <torsional>
                <ode/>
              </torsional>
              <ode/>
            </friction>
          </surface>
        </collision>
        <visual name='Wall_1_Visual'>
          <pose>0 0 1.25 0 -0 0</pose>
          <geometry>
            <box>
              <size>12 0.15 2.5</size>
            </box>
          </geometry>
          <material>
            <script>
              <uri>file://media/materials/scripts/gazebo.material</uri>
              <name>Gazebo/Grey</name>
            </script>
            <ambient>1 1 1 1</ambient>
          </material>
          <meta>
            <layer>0</layer>
          </meta>
        </visual>
        <pose>10.5 -4.8 0 0 -0 0</pose>
        <self_collide>0</self_collide>
        <enable_wind>0</enable_wind>
        <kinematic>0</kinematic>
      </link>
      <link name='Wall_10'>
        <collision name='Wall_10_Collision'>
          <geometry>
            <box>
              <size>5.25 0.15 2.5</size>
            </box>
          </geometry>
          <pose>0 0 1.25 0 -0 0</pose>
          <max_contacts>10</max_contacts>
          <surface>
            <contact>
              <ode/>
            </contact>
            <bounce/>
            <friction>
              <torsional>
                <ode/>
              </torsional>
              <ode/>
            </friction>
          </surface>
        </collision>
        <visual name='Wall_10_Visual'>
          <pose>0 0 1.25 0 -0 0</pose>
          <geometry>
            <box>
              <size>5.25 0.15 2.5</size>
            </box>
          </geometry>
          <material>
            <script>
              <uri>file://media/materials/scripts/gazebo.material</uri>
              <name>Gazebo/Grey</name>
            </script>
            <ambient>1 1 1 1</ambient>
          </material>
          <meta>
            <layer>0</layer>
          </meta>
        </visual>
        <pose>5.57112 -0.677592 0 0 -0 -0.523599</pose>
        <self_collide>0</self_collide>
        <enable_wind>0</enable_wind>
        <kinematic>0</kinematic>
      </link>
      <link name='Wall_12'>
        <collision name='Wall_12_Collision'>
          <geometry>
            <box>
              <size>5.25 0.15 2.5</size>
            </box>
          </geometry>
          <pose>0 0 1.25 0 -0 0</pose>
          <max_contacts>10</max_contacts>
          <surface>
            <contact>
              <ode/>
            </contact>
            <bounce/>
            <friction>
              <torsional>
                <ode/>
              </torsional>
              <ode/>
            </friction>
          </surface>
        </collision>
        <visual name='Wall_12_Visual'>
          <pose>0 0 1.25 0 -0 0</pose>
          <geometry>
            <box>
              <size>5.25 0.15 2.5</size>
            </box>
          </geometry>
          <material>
            <script>
              <uri>file://media/materials/scripts/gazebo.material</uri>
              <name>Gazebo/Grey</name>
            </script>
            <ambient>1 1 1 1</ambient>
          </material>
          <meta>
            <layer>0</layer>
          </meta>
        </visual>
        <pose>9.60261 0.870273 0 0 -0 -0.523599</pose>
        <self_collide>0</self_collide>
        <enable_wind>0</enable_wind>
        <kinematic>0</kinematic>
      </link>
      <link name='Wall_14'>
        <collision name='Wall_14_Collision'>
          <geometry>
            <box>
              <size>3.75 0.15 2.5</size>
            </box>
          </geometry>
          <pose>0 0 1.25 0 -0 0</pose>
          <max_contacts>10</max_contacts>
          <surface>
            <contact>
              <ode/>
            </contact>
            <bounce/>
            <friction>
              <torsional>
                <ode/>
              </torsional>
              <ode/>
            </friction>
          </surface>
        </collision>
        <visual name='Wall_14_Visual'>
          <pose>0 0 1.25 0 -0 0</pose>
          <geometry>
            <box>
              <size>3.75 0.15 2.5</size>
            </box>
          </geometry>
          <material>
            <script>
              <uri>file://media/materials/scripts/gazebo.material</uri>
              <name>Gazebo/Grey</name>
            </script>
            <ambient>1 1 1 1</ambient>
          </material>
          <meta>
            <layer>0</layer>
          </meta>
        </visual>
        <pose>-12.1593 1.05473 0 0 -0 0</pose>
        <self_collide>0</self_collide>
        <enable_wind>0</enable_wind>
        <kinematic>0</kinematic>
      </link>
      <link name='Wall_15'>
        <collision name='Wall_15_Collision'>
          <geometry>
            <box>
              <size>3.25 0.15 2.5</size>
            </box>
          </geometry>
          <pose>0 0 1.25 0 -0 0</pose>
          <max_contacts>10</max_contacts>
          <surface>
            <contact>
              <ode/>
            </contact>
            <bounce/>
            <friction>
              <torsional>
                <ode/>
              </torsional>
              <ode/>
            </friction>
          </surface>
        </collision>
        <visual name='Wall_15_Visual'>
          <pose>0 0 1.25 0 -0 0</pose>
          <geometry>
            <box>
              <size>3.25 0.15 2.5</size>
            </box>
          </geometry>
          <material>
            <script>
              <uri>file://media/materials/scripts/gazebo.material</uri>
              <name>Gazebo/Grey</name>
            </script>
            <ambient>1 1 1 1</ambient>
          </material>
          <meta>
            <layer>0</layer>
          </meta>
        </visual>
        <pose>-10.3593 -0.495268 0 0 -0 -1.5708</pose>
        <self_collide>0</self_collide>
        <enable_wind>0</enable_wind>
        <kinematic>0</kinematic>
      </link>
      <link name='Wall_2'>
        <collision name='Wall_2_Collision'>
          <geometry>
            <box>
              <size>9.75 0.15 2.5</size>
            </box>
          </geometry>
          <pose>0 0 1.25 0 -0 0</pose>
          <max_contacts>10</max_contacts>
          <surface>
            <contact>
              <ode/>
            </contact>
            <bounce/>
            <friction>
              <torsional>
                <ode/>
              </torsional>
              <ode/>
            </friction>
          </surface>
        </collision>
        <visual name='Wall_2_Visual'>
          <pose>0 0 1.25 0 -0 0</pose>
          <geometry>
            <box>
              <size>9.75 0.15 2.5</size>
            </box>
          </geometry>
          <material>
            <script>
              <uri>file://media/materials/scripts/gazebo.material</uri>
              <name>Gazebo/Grey</name>
            </script>
            <ambient>1 1 1 1</ambient>
          </material>
          <meta>
            <layer>0</layer>
          </meta>
        </visual>
        <pose>16.425 -0 0 0 -0 1.5708</pose>
        <self_collide>0</self_collide>
        <enable_wind>0</enable_wind>
        <kinematic>0</kinematic>
      </link>
      <link name='Wall_3'>
        <collision name='Wall_3_Collision'>
          <geometry>
            <box>
              <size>33 0.15 2.5</size>
            </box>
          </geometry>
          <pose>0 0 1.25 0 -0 0</pose>
          <max_contacts>10</max_contacts>
          <surface>
            <contact>
              <ode/>
            </contact>
            <bounce/>
            <friction>
              <torsional>
                <ode/>
              </torsional>
              <ode/>
            </friction>
          </surface>
        </collision>
        <visual name='Wall_3_Visual'>
          <pose>0 0 1.25 0 -0 0</pose>
          <geometry>
            <box>
              <size>33 0.15 2.5</size>
            </box>
          </geometry>
          <material>
            <script>
              <uri>file://media/materials/scripts/gazebo.material</uri>
              <name>Gazebo/Grey</name>
            </script>
            <ambient>1 1 1 1</ambient>
          </material>
          <meta>
            <layer>0</layer>
          </meta>
        </visual>
        <pose>-0 4.8 0 0 -0 3.14159</pose>
        <self_collide>0</self_collide>
        <enable_wind>0</enable_wind>
        <kinematic>0</kinematic>
      </link>
      <link name='Wall_4'>
        <collision name='Wall_4_Collision'>
          <geometry>
            <box>
              <size>9.75 0.15 2.5</size>
            </box>
          </geometry>
          <pose>0 0 1.25 0 -0 0</pose>
          <max_contacts>10</max_contacts>
          <surface>
            <contact>
              <ode/>
            </contact>
            <bounce/>
            <friction>
              <torsional>
                <ode/>
              </torsional>
              <ode/>
            </friction>
          </surface>
        </collision>
        <visual name='Wall_4_Visual'>
          <pose>0 0 1.25 0 -0 0</pose>
          <geometry>
            <box>
              <size>9.75 0.15 2.5</size>
            </box>
          </geometry>
          <material>
            <script>
              <uri>file://media/materials/scripts/gazebo.material</uri>
              <name>Gazebo/Grey</name>
            </script>
            <ambient>1 1 1 1</ambient>
          </material>
          <meta>
            <layer>0</layer>
          </meta>
        </visual>
        <pose>-16.425 -0 0 0 -0 -1.5708</pose>
        <self_collide>0</self_collide>
        <enable_wind>0</enable_wind>
        <kinematic>0</kinematic>
      </link>
      <link name='Wall_5'>
        <collision name='Wall_5_Collision'>
          <geometry>
            <box>
              <size>20 0.15 2.5</size>
            </box>
          </geometry>
          <pose>0 0 1.25 0 -0 0</pose>
          <max_contacts>10</max_contacts>
          <surface>
            <contact>
              <ode/>
            </contact>
            <bounce/>
            <friction>
              <torsional>
                <ode/>
              </torsional>
              <ode/>
            </friction>
          </surface>
        </collision>
        <visual name='Wall_5_Visual'>
          <pose>0 0 1.25 0 -0 0</pose>
          <geometry>
            <box>
              <size>20 0.15 2.5</size>
            </box>
          </geometry>
          <material>
            <script>
              <uri>file://media/materials/scripts/gazebo.material</uri>
              <name>Gazebo/Grey</name>
            </script>
            <ambient>1 1 1 1</ambient>
          </material>
          <meta>
            <layer>0</layer>
          </meta>
        </visual>
        <pose>-6.5 -4.8 0 0 -0 0</pose>
        <self_collide>0</self_collide>
        <enable_wind>0</enable_wind>
        <kinematic>0</kinematic>
      </link>
      <link name='Wall_7'>
        <collision name='Wall_7_Collision'>
          <geometry>
            <box>
              <size>6 0.15 2.5</size>
            </box>
          </geometry>
          <pose>0 0 1.25 0 -0 0</pose>
          <max_contacts>10</max_contacts>
          <surface>
            <contact>
              <ode/>
            </contact>
            <bounce/>
            <friction>
              <torsional>
                <ode/>
              </torsional>
              <ode/>
            </friction>
          </surface>
        </collision>
        <visual name='Wall_7_Visual'>
          <pose>0 0 1.25 0 -0 0</pose>
          <geometry>
            <box>
              <size>6 0.15 2.5</size>
            </box>
          </geometry>
          <material>
            <script>
              <uri>file://media/materials/scripts/gazebo.material</uri>
              <name>Gazebo/Grey</name>
            </script>
            <ambient>1 1 1 1</ambient>
          </material>
          <meta>
            <layer>0</layer>
          </meta>
        </visual>
        <pose>-7.76781 0.708107 0 0 -0 1.5708</pose>
        <self_collide>0</self_collide>
        <enable_wind>0</enable_wind>
        <kinematic>0</kinematic>
      </link>
      <link name='Wall_9'>
        <collision name='Wall_9_Collision'>
          <geometry>
            <box>
              <size>6.25 0.15 2.5</size>
            </box>
          </geometry>
          <pose>0 0 1.25 0 -0 0</pose>
          <max_contacts>10</max_contacts>
          <surface>
            <contact>
              <ode/>
            </contact>
            <bounce/>
            <friction>
              <torsional>
                <ode/>
              </torsional>
              <ode/>
            </friction>
          </surface>
        </collision>
        <visual name='Wall_9_Visual'>
          <pose>0 0 1.25 0 -0 0</pose>
          <geometry>
            <box>
              <size>6.25 0.15 2.5</size>
            </box>
          </geometry>
          <material>
            <script>
              <uri>file://media/materials/scripts/gazebo.material</uri>
              <name>Gazebo/Grey</name>
            </script>
            <ambient>1 1 1 1</ambient>
          </material>
          <meta>
            <layer>0</layer>
          </meta>
        </visual>
        <pose>0.312757 0.597408 0 0 -0 0</pose>
        <self_collide>0</self_collide>
        <enable_wind>0</enable_wind>
        <kinematic>0</kinematic>
      </link>
      <static>1</static>
    </model>
    <state world_name='default'>
      <sim_time>5 712000000</sim_time>
      <real_time>9 805993656</real_time>
      <wall_time>1697632166 57044289</wall_time>
      <iterations>5712</iterations>
      <model name='diablo'>
        <pose>-2.2e-05 -2e-06 0.285879 -2e-06 -9.3e-05 -9.7e-05</pose>
        <scale>1 1 1</scale>
        <link name='Body'>
          <pose>-2.2e-05 -2e-06 0.285879 -2e-06 -9.3e-05 -9.7e-05</pose>
          <velocity>5.7e-05 -2e-06 2e-06 1e-05 -4.6e-05 -0.000276</velocity>
          <acceleration>0.00014 0.000596 -0.000745 -0.000236 -0.005225 0.00023</acceleration>
          <wrench>0.000945 0.004011 -0.005012 0 -0 0</wrench>
        </link>
        <link name='Leg0_L'>
          <pose>-1e-05 0.123748 0.285879 3e-06 -0.783058 3.14149</pose>
          <velocity>9.1e-05 -2e-06 4e-06 8e-06 1e-06 -0.000276</velocity>
          <acceleration>3.8e-05 0.000579 -0.000719 2.98142 1.10119 -1.30316</acceleration>
          <wrench>9.4e-05 0.001426 -0.00177 0 -0 0</wrench>
        </link>
        <link name='Leg0_R'>
          <pose>-3.4e-05 -0.123802 0.285879 -4e-06 0.783212 -9.9e-05</pose>
          <velocity>2.2e-05 -2e-06 1e-06 1.2e-05 -6.5e-05 -0.000277</velocity>
          <acceleration>7.1e-05 0.000594 -0.000766 1.37122 0.401158 -0.604608</acceleration>
          <wrench>0.000176 0.001461 -0.001884 0 -0 0</wrench>
        </link>
        <link name='Leg1_L'>
          <pose>-5e-06 0.176248 0.285879 -1e-06 -0.839569 -9.6e-05</pose>
          <velocity>0.000105 -1e-06 4e-06 7e-06 -8e-05 -0.00028</velocity>
          <acceleration>6.2e-05 0.000558 -0.000603 -2.16903 -1.07905 -2.86936</acceleration>
          <wrench>7.7e-05 0.000696 -0.000752 0 -0 0</wrench>
        </link>
        <link name='Leg1_R'>
          <pose>-3.9e-05 -0.176252 0.285879 5e-06 0.839491 3.1415</pose>
          <velocity>8e-06 -2e-06 0 1.6e-05 -4.2e-05 -0.000274</velocity>
          <acceleration>0.000135 0.000584 -0.000842 -0.568142 -1.04842 2.25402</acceleration>
          <wrench>0.000168 0.000728 -0.00105 0 -0 0</wrench>
        </link>
        <link name='Leg2_L'>
          <pose>-0.063494 0.192254 0.22209 -5e-06 -0.839573 -9.1e-05</pose>
          <velocity>0.000105 1.6e-05 2e-06 -4.9e-05 -0.000166 -0.000223</velocity>
          <acceleration>-9.1e-05 0.000312 -7e-05 -1.46 -0.124189 0.853531</acceleration>
          <wrench>-9e-06 3.2e-05 -7e-06 0 -0 0</wrench>
        </link>
        <link name='Leg2_R'>
          <pose>-0.06354 -0.176246 0.222101 -1e-05 -0.839494 -8.8e-05</pose>
          <velocity>7e-06 2.1e-05 -4e-06 -6.2e-05 -0.000104 -0.000243</velocity>
          <acceleration>-0.000443 0.0002 0.000259 -0.532623 -0.046444 0.311289</acceleration>
          <wrench>-4.5e-05 2e-05 2.7e-05 0 -0 0</wrench>
        </link>
        <link name='Leg3_L'>
          <pose>0.005445 0.215498 0.093162 1e-06 -0.783056 3.14149</pose>
          <velocity>0.000126 -2e-06 1.2e-05 3e-06 -9e-06 -0.000279</velocity>
          <acceleration>0.000101 0.000212 2e-06 -0.402531 0.074454 -0.733446</acceleration>
          <wrench>0.000132 0.000275 2e-06 0 -0 0</wrench>
        </link>
        <link name='Leg3_R'>
          <pose>0.005381 -0.215503 0.09317 -5e-06 0.783211 -0.0001</pose>
          <velocity>2e-06 -1e-06 2e-06 1.6e-05 3e-06 -0.000279</velocity>
          <acceleration>0.000154 0.000315 -1.3e-05 0.414586 0.019099 -0.135574</acceleration>
          <wrench>0.0002 0.000408 -1.7e-05 0 -0 0</wrench>
        </link>
        <link name='Wheel_L'>
          <pose>0.005448 0.246248 0.093162 0 -0.058448 3.1415</pose>
          <velocity>0.000134 -2e-06 1.2e-05 8e-06 0.001456 -0.000279</velocity>
          <acceleration>0.000113 0.000179 1.2e-05 -0.001672 0.001223 -0.000241</acceleration>
          <wrench>0.000154 0.000243 1.7e-05 0 -0 0</wrench>
        </link>
        <link name='Wheel_R'>
          <pose>0.005378 -0.246253 0.09317 -4e-06 0.057661 -9.7e-05</pose>
          <velocity>-7e-06 -1e-06 2e-06 1.4e-05 -8.6e-05 -0.000274</velocity>
          <acceleration>0.000181 0.000295 -2.9e-05 -0.002841 0.001953 8.8e-05</acceleration>
          <wrench>0.000247 0.000401 -3.9e-05 0 -0 0</wrench>
        </link>
        <link name='base_link'>
          <pose>-2.2e-05 -2e-06 0.285879 -2e-06 -9.3e-05 -9.7e-05</pose>
          <velocity>5.7e-05 -1e-06 3e-06 1e-05 -4.6e-05 -0.000276</velocity>
          <acceleration>-0.000582 0.000581 -0.00082 0.000395 -0.005181 0.000282</acceleration>
          <wrench>-0.000489 0.000488 -0.000688 0 -0 0</wrench>
        </link>
        <link name='imu_link'>
          <pose>-2.2e-05 -2e-06 0.285879 -2e-06 -9.3e-05 -9.7e-05</pose>
          <velocity>5.7e-05 -1e-06 3e-06 1e-05 -4.6e-05 -0.000276</velocity>
          <acceleration>0.000104 0.000593 -0.000818 0.000297 -0.005233 0.000276</acceleration>
          <wrench>1e-05 5.9e-05 -8.2e-05 0 -0 0</wrench>
        </link>
      </model>
      <model name='environment'>
        <pose>0.248998 1.31866 0 0 -0 0</pose>
        <scale>1 1 1</scale>
        <link name='Wall_1'>
          <pose>10.749 -3.48134 0 0 -0 0</pose>
          <velocity>0 0 0 0 -0 0</velocity>
          <acceleration>0 0 0 0 -0 0</acceleration>
          <wrench>0 0 0 0 -0 0</wrench>
        </link>
        <link name='Wall_10'>
          <pose>5.82012 0.641068 0 0 0 -0.523599</pose>
          <velocity>0 0 0 0 -0 0</velocity>
          <acceleration>0 0 0 0 -0 0</acceleration>
          <wrench>0 0 0 0 -0 0</wrench>
        </link>
        <link name='Wall_12'>
          <pose>9.85161 2.18893 0 0 0 -0.523599</pose>
          <velocity>0 0 0 0 -0 0</velocity>
          <acceleration>0 0 0 0 -0 0</acceleration>
          <wrench>0 0 0 0 -0 0</wrench>
        </link>
        <link name='Wall_14'>
          <pose>-11.9103 2.37339 0 0 -0 0</pose>
          <velocity>0 0 0 0 -0 0</velocity>
          <acceleration>0 0 0 0 -0 0</acceleration>
          <wrench>0 0 0 0 -0 0</wrench>
        </link>
        <link name='Wall_15'>
          <pose>-10.1103 0.823392 0 0 0 -1.5708</pose>
          <velocity>0 0 0 0 -0 0</velocity>
          <acceleration>0 0 0 0 -0 0</acceleration>
          <wrench>0 0 0 0 -0 0</wrench>
        </link>
        <link name='Wall_2'>
          <pose>16.674 1.31866 0 0 -0 1.5708</pose>
          <velocity>0 0 0 0 -0 0</velocity>
          <acceleration>0 0 0 0 -0 0</acceleration>
          <wrench>0 0 0 0 -0 0</wrench>
        </link>
        <link name='Wall_3'>
          <pose>0.248998 6.11866 0 0 -0 3.14159</pose>
          <velocity>0 0 0 0 -0 0</velocity>
          <acceleration>0 0 0 0 -0 0</acceleration>
          <wrench>0 0 0 0 -0 0</wrench>
        </link>
        <link name='Wall_4'>
          <pose>-16.176 1.31866 0 0 0 -1.5708</pose>
          <velocity>0 0 0 0 -0 0</velocity>
          <acceleration>0 0 0 0 -0 0</acceleration>
          <wrench>0 0 0 0 -0 0</wrench>
        </link>
        <link name='Wall_5'>
          <pose>-6.251 -3.48134 0 0 -0 0</pose>
          <velocity>0 0 0 0 -0 0</velocity>
          <acceleration>0 0 0 0 -0 0</acceleration>
          <wrench>0 0 0 0 -0 0</wrench>
        </link>
        <link name='Wall_7'>
          <pose>-7.51881 2.02677 0 0 -0 1.5708</pose>
          <velocity>0 0 0 0 -0 0</velocity>
          <acceleration>0 0 0 0 -0 0</acceleration>
          <wrench>0 0 0 0 -0 0</wrench>
        </link>
        <link name='Wall_9'>
          <pose>0.561755 1.91607 0 0 -0 0</pose>
          <velocity>0 0 0 0 -0 0</velocity>
          <acceleration>0 0 0 0 -0 0</acceleration>
          <wrench>0 0 0 0 -0 0</wrench>
        </link>
      </model>
      <model name='ground_plane'>
        <pose>0 0 0 0 -0 0</pose>
        <scale>1 1 1</scale>
        <link name='link'>
          <pose>0 0 0 0 -0 0</pose>
          <velocity>0 0 0 0 -0 0</velocity>
          <acceleration>0 0 0 0 -0 0</acceleration>
          <wrench>0 0 0 0 -0 0</wrench>
        </link>
      </model>
      <light name='sun'>
        <pose>0 0 10 0 -0 0</pose>
      </light>
    </state>
  </world>
</sdf>
